Workbook

Sheet Tracing New Correction
A1: CT | B1: FRAME PID | C1: INVOICE | D1: Pid.invoice | E1: ISSUE | F1: PERCENTAGE | G1: FRAME TYPE | H1: A | I1: B | J1: CIRC R | K1: CIRC L | L1: AFTER | M1: A1 | N1: B1 | O1: CIRC R1 | P1: CIRC L1 | Q1: REMARK | R1: DONE BY
A2: 46195.868 | B2: 241187 | C2: IN26034K | D2: =B2&"."&C2 -> 241187.IN26034K | E2: SMALL | F2: 0.013 | G2: FULL RIM | H2: 49.8 | I2: 38.95 | J2: 148.15 | K2: 148.37 | L2: TRACING | M2: 49.96 | N2: 39.15 | O2: 148.64 | P2: 148.25 | Q2: SMALL | R2: AMIRUN
A3: 46198 | B3: 220126 | C3: H2630 | D3: 220126.H2630 | E3: W/SHAPE | F3: 0.0714 | G3: FULL RIM | H3: 53.11 | I3: 31.73 | J3: 146.81 | K3: 147.16 | L3: TRACING | M3: 53.34 | N3: 32.2 | O3: 147.97 | P3: 147.21 | Q3: W/SHAPE | R3: ANJALI
A4: 46198.424 | B4: 217022 | C4: CIN-000001644019 | D4: 217022.CIN-000001644019 | E4: SMALL | F4: 0.129 | G4: FULL RIM | H4: 52.69 | I4: 41.36 | J4: 160.11 | K4: 160.11 | L4: TRACING | M4: 53.11 | N4: 41.63 | O4: 160.8 | P4: 160.77 | Q4: SMALL | R4: ANJALI
A5: 46198.426 | B5: 241210 | C5: .IN26037D | D5: 241210.IN26037D | E5: SMALL | F5: 0.06 | G5: FULL RIM | H5: 50 | I5: 38.96 | J5: 148.11 | K5: 148.11 | L5: TRACING | M5: 50.11 | N5: 39.28 | O5: 148.78 | P5: 148.78 | Q5: SMALL | R5: ANJALI
A6: 46199.402 | B6: 137935 | C6: FS2605A | D6: 137935.FS2605A | E6: SMALL | F6: 0.095 | G6: FULL RIM | H6: 53.49 | I6: 38.5 | J6: 148.44 | K6: 148.82 | L6: TRACING | M6: 53.51 | N6: 38.98 | O6: 149.29 | P6: 149.12 | Q6: SMALL | R6: ANJALI
A7: 46199.406 | B7: 239839 | D7: =B7&"."&C7 -> 239839. | E7: SMALL | F7: 0.109 | G7: FULL RIM | H7: 53.82 | I7: 36.01 | J7: 154.03 | K7: 153.97 | L7: TRACING | M7: 53.6 | N7: 36.39 | O7: 154.47 | P7: 154.28 | Q7: SMALL | R7: ANJALI
A8: 46199.409 | B8: 224781 | C8: IN24062K | D8: 224781.IN24062K | E8: SMALL | F8: 0.5 | G8: FULL RIM | H8: 52.68 | I8: 42.5 | J8: 155.8 | K8: 155.8 | L8: TRACING | M8: 52.62 | N8: 42.78 | O8: 155.79 | P8: 155.29 | Q8: SMALL | R8: ANJALI
A9: 46199.453 | B9: 149862 | C9: LM2622 | D9: 149862.LM2622 | E9: SMALL | F9: 0.073 | G9: FULL RIM | H9: 46.31 | I9: 35.38 | J9: 136 | K9: 136.03 | L9: TRACING | M9: 46.38 | N9: 35.62 | O9: 136.61 | P9: 136.67 | Q9: SMALL | R9: ANJALI
A10: 46199.457 | B10: 204342 | C10: LM2620 | D10: 204342.LM2620 | E10: SMALL | F10: 0.115 | G10: FULL RIM | H10: 46.52 | I10: 39.07 | J10: 137.64 | K10: 137.68 | L10: TRACING | M10: 46.13 | N10: 39.18 | O10: 137.06 | P10: 137.12 | Q10: SMALL | R10: ANJALI
A11: 46199.464 | B11: 242242 | C11: KC078260402 | D11: 242242.KC078260402 | E11: SMALL | F11: 0.012 | G11: FULL RIM | H11: 53.4 | I11: 38.49 | J11: 150.42 | K11: 150.42 | L11: TRACING | M11: 53.32 | N11: 38.51 | O11: 150.86 | P11: 150.73 | Q11: SMALL | R11: ANJALI
A12: 46199.466 | B12: 211307 | D12: =B12&"."&C12 -> 211307. | E12: SMALL | F12: 0.2 | G12: FULL RIM | H12: 52.62 | I12: 37.76 | J12: 145.67 | K12: 145.78 | L12: TRACING | M12: 52.41 | N12: 37.61 | O12: 145.43 | P12: 144.84 | Q12: SMALL | R12: ANJALI
A13: 46199.539 | B13: 219829 | C13: LSK20260528-A1 | D13: 219829.LSK20260528-A1 | E13: BIG | F13: 0.065 | G13: FULL RIM | H13: 54.48 | I13: 41.95 | J13: 161.8 | K13: 161.88 | L13: TRACING | M13: 54.33 | N13: 41.86 | O13: 161.52 | P13: 161.52 | Q13: BIG | R13: ANJALI
A14: 46202.656 | C14: CT39267 | D14: 241185.IN26034J | E14: SMALL | F14: 0.013 | G14: FULL RIM | H14: 50.03 | I14: 38.96 | J14: 148.3 | K14: 148.24 | L14: TRACING | M14: 50.05 | N14: 39.18 | O14: 148.59 | P14: 148.42 | Q14: SMALL | R14: AMIRUN
A15: 46203.642 | D15: 134949.IN026050803D | E15: SMALL | G15: HALF RIM | H15: 56.15 | I15: 45.43 | J15: 169.6 | K15: 169.6 | L15: TRACING | M15: 56.59 | N15: 45.5 | O15: 170.54 | P15: 170.54 | Q15: SMALL | R15: AMIRUN
A16: 46203.724 | C16: 0 | D16: 134949.IN026051603B | E16: SMALL | G16: HALF RIM | H16: 55.94 | I16: 45.62 | J16: 169.42 | K16: 169.42 | L16: TRACING | M16: 56.29 | N16: 45.89 | O16: 170.56 | P16: 170.56 | Q16: SMALL | R16: AMIRUN
A17: 46207.291 | D17: 146619.26WLS-170B | E17: SMALL | G17: FULL RIM | H17: 49.3 | I17: 43.97 | J17: 152 | K17: 147.27 | L17: TRACING | M17: 49.29 | N17: 43.7 | O17: 151.98 | P17: 151.99 | Q17: SMALL | R17: AMIRUN
A18: 46207.432 | D18: 242763.IN26032K | E18: SMALL | G18: FULL RIM | H18: 49.84 | I18: 39.2 | J18: 148.23 | K18: 148.22 | L18: TRACING | M18: 50.09 | N18: 39.41 | O18: 148.98 | P18: 148.68 | Q18: SMALL | R18: AMIRUN
A19: 46210.774 | D19: 207481.IHR127B2C0001820 | E19: SMALL | G19: FULL RIM | H19: 50.84 | I19: 42.86 | J19: 153.97 | K19: 153.66 | L19: TRACING | M19: 51.5 | N19: 42.81 | O19: 155.12 | P19: 154.28 | Q19: SMALL | R19: AMIRUN
A20: 46210.776 | D20: 238613.CIN-000001387618 | E20: SMALL | G20: FULL RIM | H20: 50.58 | I20: 42.87 | J20: 152.23 | K20: 152.27 | L20: TRACING | M20: 49.7 | N20: 42.49 | O20: 150.4 | P20: 150.33 | Q20: SMALL | R20: AMIRUN
A21: 46241 | D21: 234800.IRJ127B2C0000209 | E21: SMALL | G21: FULL RIM | H21: 47.1 | I21: 41.49 | J21: 144.13 | K21: 144.13 | L21: TRACING | M21: 48.69 | N21: 42.23 | O21: 147.41 | P21: 146.47 | Q21: SMALL | R21: DEVENDRA
A22: 46212.781 | D22: 241132 | E22: SMALL | G22: FULL RIM | H22: 55.88 | I22: 46.66 | J22: 169.75 | K22: 169.62 | L22: TRACING | M22: 56.44 | N22: 46.8 | O22: 171.27 | P22: 170.83 | Q22: SMALL | R22: AMIRUN
A23: 46214.769 | D23: 207481.IN26034L | E23: SMALL | G23: FULL RIM | H23: 50.61 | I23: 42.89 | J23: 153.59 | K23: 153.93 | L23: TRACING | M23: 50.78 | N23: 43.07 | O23: 153.87 | P23: 153.75 | Q23: SMALL | R23: AMIRUN
A24: 46214.77 | D24: 149861.LM2622C | E24: SMALL | G24: FULL RIM | H24: 44.26 | I24: 36.87 | J24: 131.02 | K24: 130.39 | L24: TRACING | M24: 44.4 | N24: 37.1 | O24: 131.52 | P24: 131.57 | Q24: SMALL | R24: AMIRUN
A25: 46214.788 | D25: 234796 | E25: BIG | G25: FULL RIM | H25: 50.22 | I25: 46.92 | J25: 158.2 | K25: 158.2 | L25: TRACING | M25: 49.12 | N25: 43.7 | O25: 151.74 | P25: 151.86 | Q25: BIG | R25: AMIRUN
A26: 46214.911 | D26: 241097.IRJ127B2C0001228 | E26: BIG | G26: FULL RIM | H26: 53.5 | I26: 41.89 | J26: 157.19 | K26: 156.95 | L26: TRACING | M26: 53.29 | N26: 41.5 | O26: 156.17 | P26: 155.84 | Q26: BIG | R26: AMIRUN
A27: 46214.927 | D27: 220376 | E27: W/SHAPE | G27: FULL RIM | H27: 54.93 | I27: 49.26 | J27: 169.96 | K27: 170.19 | L27: TRACING | M27: 54.93 | N27: 49.26 | O27: 169.96 | P27: 170.19 | Q27: W/SHAPE | R27: AMIRUN
A28: 14-07-2026 | D28: 234796.CIN-000001467074 | E28: BIG | G28: FULL RIM | H28: 50.15 | I28: 46.93 | J28: 158.2 | K28: 158.14 | L28: TRACING | M28: 48.79 | N28: 43.6 | O28: 151.49 | P28: 151.49 | Q28: BIG | R28: DEVENDRA
A29: 46217.754 | D29: 207671 | E29: BIG | G29: FULL RIM | H29: 52.13 | I29: 42.76 | J29: 155.98 | K29: 153.59 | L29: TRACING | M29: 50.81 | N29: 42.89 | O29: 153.64 | P29: 153.75 | Q29: BIG | R29: DEVENDRA
A30: 46217.869 | D30: 228997.FKS26199O | E30: W/SHAPE | G30: FULL RIM | H30: 52.73 | I30: 36.4 | J30: 151.68 | K30: 151.52 | L30: TRACING | M30: 52.73 | N30: 36.42 | O30: 151.74 | P30: 151.74 | Q30: W/SHAPE | R30: AMIRUN
A31: 46217.872 | D31: 206728.FKS26191F | E31: W/SHAPE | G31: FULL RIM | H31: 50.78 | I31: 34.55 | J31: 146.94 | K31: 146.97 | L31: TRACING | M31: 50.66 | N31: 34.74 | O31: 146.27 | P31: 146.27 | Q31: W/SHAPE | R31: AMIRUN
A32: 46218.658 | D32: 243247.FKS26166F | E32: W/SHAPE | G32: FULL RIM | H32: 53.99 | I32: 41.37 | J32: 154.02 | K32: 154.59 | L32: TRACING | M32: 54.06 | N32: 40.97 | O32: 153.47 | P32: 154.32 | Q32: W/SHAPE | R32: DEVENDRA
A33: 46218.673 | D33: 222575.FKS26200G | E33: BIG | G33: FULL RIM | H33: 53.4 | I33: 43.26 | J33: 159.7 | K33: 159.7 | L33: TRACING | M33: 53.42 | N33: 42.82 | O33: 158.75 | P33: 158.56 | Q33: BIG | R33: DEVENDRA
A34: 46218.736 | D34: 206126.FKS26201B | E34: BIG | G34: FULL RIM | H34: 52.91 | I34: 42.04 | J34: 157.86 | K34: 157.99 | L34: TRACING | M34: 52.8 | N34: 41.67 | O34: 157.19 | P34: 156.91 | Q34: BIG | R34: DEVENDRA
A35: 46218.739 | D35: 234796.CIN-000001462531 | E35: SMALL | G35: FULL RIM | H35: 49.13 | I35: 43.95 | J35: 152.57 | K35: 152.03 | L35: TRACING | M35: 50.46 | N35: 46.51 | O35: 157.78 | P35: 157.82 | Q35: SMALL | R35: DEVENDRA
A36: 46218.902 | D36: 225336.IRJ126B2C00013 | E36: SMALL | G36: FULL RIM | H36: 47.2 | I36: 40.78 | J36: 142.81 | K36: 142.81 | L36: TRACING | M36: 47.77 | N36: 40.82 | O36: 143.57 | P36: 143.96 | Q36: SMALL | R36: DEVENDRA
A37: 46221.19 | D37: 207671 | E37: SMALL | G37: FULL RIM | H37: 50.81 | I37: 42.89 | J37: 153.64 | K37: 153.75 | L37: TRACING | M37: 51.55 | N37: 43.66 | O37: 156.05 | P37: 156 | Q37: SMALL | R37: DHAVAL
A38: 46221.749 | D38: 207375.FKS26109G | E38: SMALL | G38: FULL RIM | H38: 53.08 | I38: 43.67 | J38: 161.39 | K38: 161.08 | L38: TRACING | M38: 52.79 | N38: 43.89 | O38: 161.32 | P38: 161.02 | Q38: SMALL | R38: AMIRUN
D39: 234796.CIN-000001467074 | E39: SMALL | G39: FULL RIM | H39: 48.79 | I39: 43.6 | J39: 151.49 | K39: 151.49 | L39: TRACING | M39: 49.81 | N39: 47.29 | O39: 158.13 | P39: 158.24 | Q39: SMALL | R39: AMIRUN
A40: 46221.759 | D40: 206132.FKS26185B | E40: BIG | G40: FULL RIM | H40: 53.58 | I40: 43.19 | J40: 160.9 | K40: 161.02 | L40: TRACING | M40: 53.3 | N40: 42.67 | O40: 160.01 | P40: 159.9 | Q40: BIG | R40: AMIRUN
...

Sheet raw
A1: PID.INVOICE | B1: Total Items | C1: QC Done (DOT) | D1: MEI Fail (DOT) | E1: MEI Fail % (DOT) | F1: First frame_type | G1: BIG | H1: SMALL | I1: CHIP | J1: WRONG SHAPE | K1: SCRATCH | L1: ISSUE | M1: PERCENTAGE
A2: 241186.IN26056C | B2: 19 | C2: 16 | D2: 3 | E2: 0.188 | F2: Full Rim | G2: 0.1875 | H2: 0 | I2: 0 | J2: 0 | K2: 0.0625 | L2: BIG | M2: 0.1875
A3: 206728.FKS26191E | B3: 43 | C3: 41 | D3: 6 | E3: 0.146 | F3: Full Rim | G3: 0.119 | H3: 0 | I3: 0.0238 | J3: 0 | K3: 0.0952 | L3: BIG | M3: 0.119
A4: 245911.FKS26218I | B4: 54 | C4: 52 | D4: 5 | E4: 0.096 | F4: Full Rim | G4: 0.0962 | H4: 0 | I4: 0 | J4: 0 | K4: 0.0385 | L4: BIG | M4: 0.0962
A5: 221172.FKS26304A | B5: 53 | C5: 52 | D5: 5 | E5: 0.096 | F5: Full Rim | G5: 0.0943 | H5: 0 | I5: 0 | J5: 0 | K5: 0.0189 | L5: BIG | M5: 0.0943
A6: 246865.FKS26210F | B6: 32 | C6: 31 | D6: 3 | E6: 0.097 | F6: Full Rim | G6: 0.0909 | H6: 0 | I6: 0 | J6: 0 | K6: 0.0606 | L6: BIG | M6: 0.0909
A7: 217659.FKS26190E | B7: 52 | C7: 53 | D7: 3 | E7: 0.057 | F7: Full Rim | G7: 0.0566 | H7: 0 | I7: 0 | J7: 0 | K7: 0.0377 | L7: BIG | M7: 0.0566
A8: 241185.IN26054E | B8: 38 | C8: 37 | D8: 4 | E8: 0.108 | F8: Full Rim | G8: 0.0541 | H8: 0.027 | I8: 0.027 | J8: 0 | K8: 0 | L8: BIG | M8: 0.0541
A9: 239021.FKS26323A | B9: 79 | C9: 79 | D9: 4 | E9: 0.051 | F9: Full Rim | G9: 0.038 | H9: 0 | I9: 0.0127 | J9: 0 | K9: 0.0253 | L9: BIG | M9: 0.038
A10: 211293.FKS26182D | B10: 55 | C10: 52 | D10: 3 | E10: 0.058 | F10: Full Rim | G10: 0.037 | H10: 0 | I10: 0.0185 | J10: 0 | K10: 0 | L10: BIG | M10: 0.037
A11: 241112.IRJ127B2C0002302 | B11: 28 | C11: 28 | D11: 3 | E11: 0.107 | F11: Full Rim | G11: 0.0714 | H11: 0 | I11: 0.0714 | J11: 0 | K11: 0 | L11: BIG/CHIP | M11: 0.0714
A12: 241100.IRJ127B2C0002100 | B12: 64 | C12: 61 | D12: 4 | E12: 0.066 | F12: Full Rim | G12: 0.0625 | H12: 0 | I12: 0.0313 | J12: 0 | K12: 0.0625 | L12: BIG/SCRATCH | M12: 0.0625
A13: 241124.IRJ127B2C0002671 | B13: 49 | C13: 47 | D13: 3 | E13: 0.064 | F13: Full Rim | G13: 0.0417 | H13: 0 | I13: 0 | J13: 0.0208 | K13: 0.0417 | L13: BIG/SCRATCH | M13: 0.0417
... A237: 241387.IN26075D | B237: 54 | C237: 53 | D237: 3 | E237: 0.057 | F237: Full Rim | G237: 0.0185 | H237: 0.037 | I237: 0.0185 | J237: 0.0185 | K237: 0 | L237: SMALL | M237: 0.037

Sheet 6-7 oct
A1: PID.INVOICE | B1: Total Items | C1: Dot Invoice % | D1: Vendor Invoice % | E1: Base Invoice % | F1: QC Done (DOT) | G1: MEI Fail (DOT) | H1: MEI Fail % (DOT) | I1: First frame_type | J1: BIG | K1: SMALL | L1: SCRATCH | M1: CHIP | N1: WRONG | O1: issue | P1: percentage
A2: 241805.IN026042004A | B2: 6 | C2: 0.5 | D2: 1 | F2: 7 | G2: 3 | H2: 0.429 | I2: Full Rim | J2: 0.4286 | K2: 0 | L2: 0 | M2: 0 | N2: 0 | O2: BIG | P2: 0.4286
A3: 241120.IRJ127B2C0002380 | B3: 13 | C3: 0.28 | D3: 1 | F3: 11 | G3: 5 | H3: 0.455 | I3: Full Rim | J3: 0.3077 | K3: 0 | L3: 0.0769 | M3: 0.1538 | N3: 0 | O3: BIG | P3: 0.3077
A4: 234768.IRJ127B2C0002729 | B4: 15 | C4: 1 | D4: 1 | F4: 15 | G4: 4 | H4: 0.267 | I4: Full Rim | J4: 0.25 | K4: 0 | L4: 0 | M4: 0.0625 | N4: 0 | O4: BIG | P4: 0.25
A5: 215405.KC078260319F | B5: 23 | C5: 0.09 | D5: 1 | F5: 22 | G5: 6 | H5: 0.273 | I5: Full Rim | J5: 0.2083 | K5: 0.0417 | L5: 0.1667 | M5: 0 | N5: 0 | O5: BIG | P5: 0.2083
A6: 241078.IRJ127B2C0003036 | B6: 11 | C6: 0.52 | D6: 1 | F6: 9 | G6: 3 | H6: 0.333 | I6: Full Rim | J6: 0.2 | K6: 0 | L6: 0 | M6: 0 | N6: 0.1 | O6: BIG | P6: 0.2
A7: 234765.IRJ127B2C0001833 | B7: 18 | C7: 0.9 | D7: 1 | F7: 15 | G7: 3 | H7: 0.2 | I7: Full Rim | J7: 0.1333 | K7: 0 | L7: 0.0667 | M7: 0 | N7: 0.0667 | O7: BIG | P7: 0.1333
A8: 253884.26WLS-407K | B8: 27 | C8: 1 | D8: 1 | F8: 27 | G8: 3 | H8: 0.111 | I8: Full Rim | J8: 0.1111 | K8: 0 | L8: 0.0741 | M8: 0 | N8: 0 | O8: BIG | P8: 0.1111
A9: 221163.FKS26375C | B9: 39 | C9: 0.43 | D9: 1 | F9: 38 | G9: 4 | H9: 0.105 | I9: Full Rim | J9: 0.0789 | K9: 0 | L9: 0 | M9: 0.0263 | N9: 0 | O9: BIG | P9: 0.0789
A10: 221172.FKS26345G | B10: 129 | C10: 0.54 | D10: 1 | F10: 125 | G10: 7 | H10: 0.056 | I10: Full Rim | J10: 0.048 | K10: 0 | L10: 0.016 | M10: 0.008 | N10: 0 | O10: BIG | P10: 0.048
A11: 240000.IN026072701J | B11: 20 | C11: 0.28 | D11: 1 | F11: 16 | G11: 7 | H11: 0.438 | I11: Full Rim | J11: 0.1579 | K11: 0.1053 | L11: 0.0526 | M11: 0.1579 | N11: 0.0526 | O11: BIG/CHIP | P11: 0.1579
A12: 246819.26WLS-379A | B12: 23 | C12: 1 | D12: 1 | F12: 19 | G12: 4 | H12: 0.211 | I12: Full Rim | J12: 0.1364 | K12: 0 | L12: 0.0909 | M12: 0.1364 | N12: 0 | O12: BIG/CHIP | P12: 0.1364
A13: 218966.IRJ127B2C0001181 | B13: 61 | C13: 0.32 | D13: 1 | F13: 54 | G13: 8 | H13: 0.148 | I13: Full Rim | J13: 0.0862 | K13: 0 | L13: 0.0172 | M13: 0.069 | N13: 0.0345 | O13: BIG/CHIP | P13: 0.0862
... A25: 241387.IN26075D | B25: 54 | C25: 1 | D25: 1 | F25: 53 | G25: 3 | H25: 0.057 | I25: Full Rim | J25: 0.0185 | K25: 0.037 | L25: 0.0185 | M25: 0.0185 | N25: 0 | O25: SMALL | P25: 0.037

Sheet 30SEP-1OCT
A1: PID.INVOICE | B1: Total Items | C1: Dot Invoice % | D1: Vendor Invoice % | E1: Base Invoice % | F1: QC Done (DOT) | G1: MEI Fail (DOT) | H1: MEI Fail % (DOT) | I1: First frame_type | J1: big | K1: small | L1: scratch | M1: wrong shape | N1: chip | O1: Issue | P1: percentage
A2: 225339.IRJ127B2C0002575-CH01 | B2: 14 | C2: 1 | D2: 1 | F2: 11 | G2: 4 | H2: 0.364 | I2: Full Rim | J2: 0.25 | K2: 0.0833 | L2: 0.1667 | M2: 0 | N2: 0 | O2: BIG | P2: 0.25
A3: 246819.26WLS-379A | B3: 12 | C3: 1 | D3: 1 | F3: 11 | G3: 3 | H3: 0.273 | I3: Full Rim | J3: 0.25 | K3: 0 | L3: 0 | M3: 0 | N3: 0 | O3: BIG | P3: 0.25
A4: 241117.IRJ127B2C0002780 | B4: 11 | C4: 0.52 | D4: 1 | F4: 7 | G4: 3 | H4: 0.429 | I4: Full Rim | J4: 0.2222 | K4: 0.1111 | L4: 0.1111 | M4: 0 | N4: 0 | O4: BIG | P4: 0.2222
A5: 241119.IRJ127B2C0002900 | B5: 48 | C5: 0.89 | D5: 1 | F5: 38 | G5: 9 | H5: 0.237 | I5: Full Rim | J5: 0.0976 | K5: 0.0244 | L5: 0.0732 | M5: 0.0488 | N5: 0.0488 | O5: BIG | P5: 0.0976
A6: 241075.IRJ127B2C0002281 | B6: 17 | C6: 0.61 | D6: 1 | F6: 12 | G6: 3 | H6: 0.25 | I6: Full Rim | J6: 0.1538 | K6: 0 | L6: 0.1538 | M6: 0 | N6: 0.0769 | O6: BIG/SCRATCH | P6: 0.1538
A7: 240000.IN026071404E | B7: 12 | C7: 0.29 | D7: 1 | F7: 8 | G7: 4 | H7: 0.5 | I7: Full Rim | J7: 0 | K7: 0 | L7: 0.1 | M7: 0 | N7: 0.4 | O7: CHIP | P7: 0.4
A8: 245914.FKS26289A | B8: 23 | C8: 0.79 | D8: 1 | F8: 21 | G8: 3 | H8: 0.143 | I8: Full Rim | J8: 0.0476 | K8: 0 | L8: 0.0476 | M8: 0 | N8: 0.0952 | O8: CHIP | P8: 0.0952
A9: 211318.26WLS-379C | B9: 53 | C9: 0.62 | D9: 1 | F9: 51 | G9: 4 | H9: 0.078 | I9: Full Rim | J9: 0.0364 | K9: 0 | L9: 0.0182 | M9: 0 | N9: 0.0545 | O9: CHIP | P9: 0.0545
A10: 239999.IN026081002E | B10: 15 | C10: 0.5 | D10: 1 | F10: 9 | G10: 3 | H10: 0.333 | I10: Full Rim | J10: 0.1 | K10: 0.1 | L10: 0.2 | M10: 0 | N10: 0.1 | O10: SCRATCH/BIG | P10: 0.2
A11: 137971.FKS26228F | B11: 30 | C11: 0.37 | D11: 1 | F11: 29 | G11: 3 | H11: 0.103 | I11: Full Rim | J11: 0.0667 | K11: 0.0333 | L11: 0.1333 | M11: 0 | N11: 0 | O11: SCRATCH/BIG | P11: 0.1333
A12: 220577.H2629 | B12: 41 | C12: 0.39 | D12: 1 | F12: 36 | G12: 7 | H12: 0.194 | I12: Full Rim | J12: 0.1053 | K12: 0 | L12: 0.1316 | M12: 0.0263 | N12: 0.0526 | O12: SCRATCH/BIG | P12: 0.1316
A13: 238757.26WLS-425K | B13: 39 | C13: 0.72 | D13: 1 | F13: 32 | G13: 3 | H13: 0.094 | I13: Full Rim | J13: 0.0278 | K13: 0 | L13: 0.1111 | M13: 0 | N13: 0.0556 | O13: SCRATCH/BIG | P13: 0.1111
... A20: 215405.KC078260319F | B20: 10 | C20: 0.11 | D20: 1 | F20: 10 | G20: 3 | H20: 0.3 | I20: Full Rim | J20: 0.0909 | K20: 0 | L20: 0.0909 | M20: 0.1818 | N20: 0 | O20: WRONG | P20: 0.1818

Sheet 2OCT-5OCT
A1: Pid.Invoice | B1: Total Items | C1: Dot Invoice % | D1: Vendor Invoice % | E1: Base Invoice % | F1: QC Done (DOT) | G1: MEI Fail (DOT) | H1: MEI Fail % (DOT) | I1: First frame_type | J1: big | K1: small | L1: scratch | M1: chip | N1: wrong | O1: issue | P1: percentage
A2: 243673.FKS26222H | B2: 26 | C2: 0.39 | D2: 1 | F2: 15 | G2: 10 | H2: 0.667 | I2: Full Rim | J2: 0.381 | K2: 0.0476 | L2: 0.1905 | M2: 0 | N2: 0.0476 | O2: BIG | P2: 0.381
A3: 225339.IRJ127B2C0002575-CH01 | B3: 26 | C3: 1 | D3: 1 | F3: 16 | G3: 5 | H3: 0.313 | I3: Full Rim | J3: 0.1818 | K3: 0 | L3: 0.0455 | M3: 0.0455 | N3: 0.0909 | O3: BIG | P3: 0.1818
A4: 243674.FKS26197M | B4: 64 | C4: 0.97 | D4: 1 | F4: 63 | G4: 5 | H4: 0.079 | I4: Full Rim | J4: 0.0635 | K4: 0.0159 | L4: 0.0159 | M4: 0 | N4: 0 | O4: BIG | P4: 0.0635
A5: 221174.FKS26158D | B5: 93 | C5: 0.18 | D5: 1 | F5: 90 | G5: 6 | H5: 0.067 | I5: Full Rim | J5: 0.0532 | K5: 0 | L5: 0.0426 | M5: 0 | N5: 0.0106 | O5: BIG | P5: 0.0532
A6: 221172.FKS26345H | B6: 201 | C6: 0.55 | D6: 1 | F6: 198 | G6: 11 | H6: 0.056 | I6: Full Rim | J6: 0.04 | K6: 0 | L6: 0.015 | M6: 0.015 | N6: 0.005 | O6: BIG | P6: 0.04
A7: 219826.LSK26090901-A6 | B7: 127 | C7: 0.2 | D7: 1 | F7: 115 | G7: 7 | H7: 0.061 | I7: Full Rim | J7: 0.042 | K7: 0 | L7: 0.042 | M7: 0.0168 | N7: 0 | O7: BIG/SCRATCH | P7: 0.042
A8: 240000.IN026071404E | B8: 16 | C8: 0.23 | D8: 1 | F8: 11 | G8: 7 | H8: 0.636 | I8: Full Rim | J8: 0.1053 | K8: 0 | L8: 0.1579 | M8: 0.3158 | N8: 0 | O8: CHIP | P8: 0.3158
A9: 242138.LSK26070602-A2 | B9: 115 | C9: 0.99 | D9: 1 | F9: 108 | G9: 13 | H9: 0.12 | I9: Full Rim | J9: 0.0182 | K9: 0.0091 | L9: 0.0273 | M9: 0.1 | N9: 0 | O9: CHIP | P9: 0.1
A10: 245915.FKS26272 | B10: 203 | C10: 1 | D10: 1 | F10: 195 | G10: 13 | H10: 0.067 | I10: Full Rim | J10: 0.0305 | K10: 0 | L10: 0.0254 | M10: 0.0457 | N10: 0 | O10: CHIP | P10: 0.0457
A11: 221176.FKS26218F | B11: 135 | C11: 0.28 | D11: 1 | F11: 127 | G11: 7 | H11: 0.055 | I11: Full Rim | J11: 0.0155 | K11: 0 | L11: 0.0233 | M11: 0.0388 | N11: 0 | O11: CHIP | P11: 0.0388
A12: 244245.LSK26090901-A4 | B12: 104 | C12: 1 | D12: 1 | F12: 97 | G12: 5 | H12: 0.052 | I12: Full Rim | J12: 0.0206 | K12: 0 | L12: 0.0825 | M12: 0.0206 | N12: 0.0103 | O12: SCRATCH | P12: 0.0825
A13: 238759.26WLS-407N | B13: 32 | C13: 0.36 | D13: 1 | F13: 31 | G13: 6 | H13: 0.194 | I13: Full Rim | J13: 0.0909 | K13: 0.0303 | L13: 0.1212 | M13: 0.0606 | N13: 0.0303 | O13: SCRATCH/BIG | P13: 0.1212
... A36: 239021.FKS26350A | B36: 76 | C36: 0.2 | D36: 1 | F36: 76 | G36: 4 | H36: 0.053 | I36: Full Rim | J36: 0.0132 | K36: 0.0263 | L36: 0.0263 | M36: 0 | N36: 0.0132 | O36: WRONG | P36: 0.0263

Sheet 28-29 SEP
A1: Pid.invoice | B1: Total Items | C1: Dot Invoice % | D1: Vendor Invoice % | E1: Base Invoice % | F1: QC Done (DOT) | G1: MEI Fail (DOT) | H1: MEI Fail % (DOT) | I1: First frame_type | J1: big | K1: small | L1: chip | M1: scrach | N1: wrong shape | O1: issue | P1: percentage | Q1: Column1
A2: 225339.IRJ127B2C0002575-CH01 | B2: 17 | C2: 1 | D2: 1 | F2: 14 | G2: 5 | H2: 0.357 | I2: Full Rim | J2: 0.1667 | K2: 0 | L2: 0 | M2: 0.0556 | N2: 0.1111 | O2: BIG | P2: 0.1667 | Q2: #N/A
A3: 137971.FKS26228H | B3: 11 | C3: 0.06 | D3: 1 | F3: 12 | G3: 3 | H3: 0.25 | I3: Full Rim | J3: 0.2308 | K3: 0 | L3: 0 | M3: 0.0769 | N3: 0 | O3: BIG | P3: 0.2308 | Q3: #N/A
A4: 207370.FKS26349C | B4: 19 | C4: 0.06 | D4: 1 | F4: 19 | G4: 3 | H4: 0.158 | I4: Full Rim | J4: 0.12 | K4: 0 | L4: 0 | M4: 0 | N4: 0 | O4: BIG | P4: 0.12 | Q4: #N/A
A5: 241100.IRJ127B2C0002611 | B5: 38 | C5: 0.29 | D5: 1 | F5: 33 | G5: 3 | H5: 0.091 | I5: Full Rim | J5: 0.0588 | K5: 0.0294 | L5: 0 | M5: 0.0294 | N5: 0 | O5: BIG | P5: 0.0588 | Q5: #N/A
A6: 221172.FKS26345G | B6: 150 | C6: 0.55 | D6: 1 | F6: 145 | G6: 15 | H6: 0.103 | I6: Full Rim | J6: 0.0476 | K6: 0.0204 | L6: 0.034 | M6: 0.0544 | N6: 0 | O6: BIG/SCRATCH | P6: 0.0544 | Q6: #N/A
A7: 207671.IHR127B2C0003243 | B7: 101 | C7: 0.07 | D7: 1 | F7: 97 | G7: 10 | H7: 0.103 | I7: Full Rim | J7: 0.0588 | K7: 0.0098 | L7: 0.0294 | M7: 0.0882 | N7: 0.0098 | O7: BIG/SCRATCH | P7: 0.0882 | Q7: #N/A
A8: 241100.IRJ127B2C0002818 | B8: 26 | C8: 0.2 | D8: 1 | F8: 26 | G8: 3 | H8: 0.115 | I8: Full Rim | J8: 0.0741 | K8: 0 | L8: 0.037 | M8: 0.1481 | N8: 0 | O8: BIG/SCRATCH | P8: 0.1481 | Q8: #N/A
A9: 225336.IRJ127B2C0002585 | B9: 64 | C9: 0.43 | D9: 1 | F9: 51 | G9: 29 | H9: 0.569 | I9: Full Rim | J9: 0.0133 | K9: 0.3467 | L9: 0 | M9: 0.0533 | N9: 0.04 | O9: SMALL | P9: 0.3467 | Q9: #N/A
A10: 243276.LSK26090901-A2 | B10: 31 | C10: 0.69 | D10: 1 | F10: 27 | G10: 9 | H10: 0.333 | I10: Full Rim | J10: 0.0323 | K10: 0.2581 | L10: 0 | M10: 0.0323 | N10: 0.0323 | O10: SMALL | P10: 0.2581 | Q10: #N/A
A11: 246230.LSK26090901-A1 | B11: 45 | C11: 0.63 | D11: 1 | F11: 41 | G11: 7 | H11: 0.171 | I11: Full Rim | J11: 0 | K11: 0.1273 | L11: 0 | M11: 0.0364 | N11: 0 | O11: SMALL | P11: 0.1273 | Q11: #N/A
A12: 239999.IN026081002E | B12: 11 | C12: 0.16 | D12: 1 | F12: 9 | G12: 5 | H12: 0.556 | I12: Full Rim | J12: 0 | K12: 0.3 | L12: 0.1 | M12: 0.1 | N12: 0.1 | O12: SMALL | P12: 0.3 | Q12: #N/A
A13: 137971.FKS26307H | B13: 35 | C13: 0.2 | D13: 1 | F13: 37 | G13: 5 | H13: 0.135 | I13: Full Rim | J13: 0.0465 | K13: 0.0698 | L13: 0 | M13: 0.0233 | N13: 0.0233 | O13: SMALL | P13: 0.0698 | Q13: #N/A
... A16: 239999.IN026062202D | B16: 12 | C16: 0.18 | D16: 1 | F16: 9 | G16: 3 | H16: 0.333 | I16: Full Rim | J16: 0.0909 | K16: 0 | L16: 0.0909 | M16: 0.0909 | N16: 0.0909 | O16: WRONG SHAPE | P16: 0.0909 | Q16: #N/A

Sheet 24-27 SEP
A1: PID.INVOICE | B1: Total Items | C1: Dot Invoice % | D1: Vendor Invoice % | E1: Base Invoice % | F1: QC Done (DOT) | G1: MEI Fail (DOT) | H1: MEI Fail % (DOT) | I1: First frame_type | J1: BIG | K1: SMALL | L1: CHIP | M1: SCRATCH | N1: WRONG SHAPE | O1: ISSUE | P1: PERCENTAGE
A2: 207481.IN24045G | B2: 6 | C2: 0.01 | D2: 1 | F2: 3 | G2: 3 | H2: 1 | I2: Full Rim | J2: 0 | K2: 0.6 | L2: 0 | M2: 0.2 | N2: 0.2 | O2: SMALL | P2: 0.6
A3: 242221.IRJ127B2C0001909 | B3: 10 | C3: 0.21 | D3: 1 | F3: 9 | G3: 7 | H3: 0.778 | I3: Full Rim | J3: 0 | K3: 0.7 | L3: 0 | M3: 0 | N3: 0 | O3: SMALL | P3: 0.7
A4: 219825.LSK26060502-A15 | B4: 13 | C4: 0.26 | D4: 1 | F4: 10 | G4: 6 | H4: 0.6 | I4: Full Rim | J4: 0.0833 | K4: 0.4167 | L4: 0 | M4: 0.0833 | N4: 0 | O4: SMALL | P4: 0.4167
A5: 231593.25Y019 | B5: 5 | C5: 1 | D5: 1 | F5: 5 | G5: 3 | H5: 0.6 | I5: Full Rim | J5: 0.1667 | K5: 0 | L5: 0 | M5: 0 | N5: 0.3333 | O5: WRONG/SHAPE | P5: 0.3333
A6: 247067.IRJ127B2C0002556 | B6: 6 | C6: 0.38 | D6: 1 | F6: 6 | G6: 3 | H6: 0.5 | I6: Full Rim | J6: 0 | K6: 0 | L6: 0 | M6: 0 | N6: 0.5 | O6: WRONG | P6: 0.5
A7: 236095.IHR127B2C0000582 | B7: 7 | C7: 0.24 | D7: 1 | F7: 7 | G7: 3 | H7: 0.429 | I7: Full Rim | J7: 0.125 | K7: 0.125 | L7: 0 | M7: 0 | N7: 0.125 | O7: WRONG | P7: 0.125
A8: 225336.IRJ127B2C0002585 | B8: 30 | C8: 0.28 | D8: 1 | F8: 26 | G8: 11 | H8: 0.423 | I8: Full Rim | J8: 0.1333 | K8: 0.2 | L8: 0 | M8: 0.2333 | N8: 0.0667 | O8: SCRATCH | P8: 0.2333
A9: 240000.IN026061604F | B9: 11 | C9: 0.14 | D9: 1 | F9: 8 | G9: 3 | H9: 0.375 | I9: Full Rim | J9: 0 | K9: 0.125 | L9: 0.125 | M9: 0 | N9: 0.125 | O9: CHIP/WRONG | P9: 0.125
A10: 234796.IRJ127B2C0002709 | B10: 9 | C10: 0.23 | D10: 1 | F10: 8 | G10: 3 | H10: 0.375 | I10: Full Rim | J10: 0 | K10: 0.3333 | L10: 0 | M10: 0 | N10: 0 | O10: SMALL | P10: 0.3333
A11: 225339.IRJ127B2C0002575-CH01 | B11: 35 | C11: 1 | D11: 1 | F11: 27 | G11: 9 | H11: 0.333 | I11: Full Rim | J11: 0.1892 | K11: 0.0541 | L11: 0.027 | M11: 0.2162 | N11: 0.027 | O11: SCRATCH | P11: 0.2162
A12: 245914.FKS26248A | B12: 31 | C12: 0.36 | D12: 1 | F12: 24 | G12: 8 | H12: 0.333 | I12: Full Rim | J12: 0.0714 | K12: 0.2143 | L12: 0 | M12: 0 | N12: 0 | O12: SMALL | P12: 0.2143
A13: 239999.IN026061604F | B13: 21 | C13: 0.25 | D13: 1 | F13: 15 | G13: 5 | H13: 0.333 | I13: Full Rim | J13: 0.0556 | K13: 0.0556 | L13: 0.1111 | M13: 0.0556 | N13: 0.0556 | O13: CHIP | P13: 0.1111
... A61: 209756.LSK26081401-A9 | B61: 103 | C61: 0.49 | D61: 1 | F61: 96 | G61: 5 | H61: 0.052 | I61: Full Rim | J61: 0.03 | K61: 0 | L61: 0.01 | M61: 0.06 | N61: 0.01 | O61: SCRATCH | P61: 0.06

Sheet 23-24 Sep
A1: PID.Invoice | B1: Total Items | C1: Dot Invoice % | D1: Vendor Invoice % | E1: Base Invoice % | F1: QC Done (DOT) | G1: MEI Fail (DOT) | H1: MEI Fail % (DOT) | I1: big | J1: small | K1: chip | L1: scratch | M1: wrong shape | N1: ISSUE | O1: PERCENTAGE | P1: First frame_type
A2: 244415.GLS-20260610-B | B2: 21 | C2: 0.68 | D2: 1 | F2: 18 | G2: 4 | H2: 0.222 | I2: 0.1905 | J2: 0 | K2: 0 | L2: 0.0476 | M2: 0 | N2: BIG | O2: 0.1905 | P2: Full Rim
A3: 206728.FKS26320B | B3: 114 | C3: 0.91 | D3: 1 | F3: 109 | G3: 6 | H3: 0.055 | I3: 0.0364 | J3: 0.0091 | K3: 0.0091 | L3: 0.0273 | M3: 0.0091 | N3: BIG | O3: 0.0364 | P3: Full Rim
A4: 218966.IRJ127B2C0001180 | B4: 97 | C4: 0.78 | D4: 1 | F4: 96 | G4: 5 | H4: 0.052 | I4: 0.051 | J4: 0.0102 | K4: 0.0102 | L4: 0.0408 | M4: 0 | N4: BIG | O4: 0.051 | P4: Full Rim
A5: 237234.26WLS-319A | B5: 34 | C5: 0.27 | D5: 1 | F5: 30 | G5: 4 | H5: 0.133 | I5: 0.0645 | J5: 0 | K5: 0.0645 | L5: 0 | M5: 0 | N5: BIG/CHIP | O5: 0.0645 | P5: Full Rim
A6: 241100.IRJ127B2C0002578 | B6: 31 | C6: 0.24 | D6: 1 | F6: 31 | G6: 4 | H6: 0.129 | I6: 0.0625 | J6: 0.0313 | K6: 0.0625 | L6: 0.0625 | M6: 0 | N6: BIG/CHIP | O6: 0.0625 | P6: Full Rim
A7: 242174.LSK26083101-A6 | B7: 48 | C7: 0.91 | D7: 1 | F7: 41 | G7: 5 | H7: 0.122 | I7: 0.0455 | J7: 0 | K7: 0.0455 | L7: 0.1136 | M7: 0.0227 | N7: BIG/CHIP | O7: 0.1136 | P7: Full Rim
A8: 150798.ZD260012A | B8: 55 | C8: 0.24 | D8: 1 | F8: 54 | G8: 4 | H8: 0.074 | I8: 0.0179 | J8: 0 | K8: 0.0536 | L8: 0 | M8: 0 | N8: CHIP | O8: 0.0536 | P8: Full Rim
A9: 246857.FKS26205N | B9: 82 | C9: 0.68 | D9: 1 | F9: 76 | G9: 4 | H9: 0.053 | I9: 0.013 | J9: 0 | K9: 0.026 | L9: 0.013 | M9: 0.013 | N9: CHIP | O9: 0.026 | P9: Full Rim
A10: 247078.IRJ127B2C0002446 | B10: 29 | C10: 1 | D10: 1 | F10: 24 | G10: 4 | H10: 0.167 | I10: 0.0769 | J10: 0 | K10: 0.0769 | L10: 0.0769 | M10: 0 | N10: CHIP/SCRATCH | O10: 0.0769 | P10: Full Rim
A11: 137934.FS2619C | B11: 61 | C11: 0.3 | D11: 1 | F11: 58 | G11: 4 | H11: 0.069 | I11: 0.0164 | J11: 0.0164 | K11: 0.0164 | L11: 0.0492 | M11: 0.0328 | N11: SCRATCH | O11: 0.0492 | P11: Full Rim
A12: 239999.IN026062202D | B12: 15 | C12: 0.21 | D12: 1 | F12: 14 | G12: 4 | H12: 0.286 | I12: 0.0588 | J12: 0.0588 | K12: 0.1176 | L12: 0.2353 | M12: 0.0588 | N12: SCRATCH/CHIP | O12: 0.2353 | P12: Full Rim
A13: 239999.IN026061604F | B13: 12 | C13: 0.17 | D13: 1 | F13: 13 | G13: 4 | H13: 0.308 | I13: 0 | J13: 0.0769 | K13: 0.0769 | L13: 0.1538 | M13: 0.1538 | N13: SCRATCH/WRONG SHAPE | O13: 0.1538 | P13: Full Rim
... A21: 239999.IN026081002E | B21: 16 | C21: 0.23 | D21: 1 | F21: 8 | G21: 5 | H21: 0.625 | I21: 0.1538 | J21: 0.1538 | K21: 0.1538 | L21: 0.1538 | M21: 0 | N21: WRONG SHAPE | O21: 0.1538 | P21: Full Rim

Sheet 20-22 Sep
A1: PID.Invoice | B1: Total Items | C1: Dot Invoice % | D1: Vendor Invoice % | E1: Base Invoice % | F1: QC Done (DOT) | G1: MEI Fail (DOT) | H1: MEI Fail % (DOT) | I1: big | J1: small | K1: chip | L1: scratch | M1: wrong shape | N1: First frame_type | O1: issue | P1: percentage
A2: 242597.FKS26314K | B2: 73 | C2: 0.48 | D2: 1 | F2: 69 | G2: 28 | H2: 0.406 | I2: 0.0842 | J2: 0.0526 | K2: 0.0105 | L2: 0.1579 | M2: 0.2316 | N2: Full Rim | O2: wrong shape | P2: 0.2316
A3: 241119.IRJ127B2C0002561 | B3: 101 | C3: 0.91 | D3: 1 | F3: 97 | G3: 23 | H3: 0.237 | I3: 0.0882 | J3: 0.0588 | K3: 0.0686 | L3: 0.098 | M3: 0.0196 | N3: Full Rim | O3: big/scratch | P3: 0.098
A4: 245915.FKS26272 | B4: 157 | C4: 1 | D4: 1 | F4: 150 | G4: 20 | H4: 0.133 | I4: 0.0449 | J4: 0.0192 | K4: 0.0705 | L4: 0.0385 | M4: 0 | N4: Full Rim | O4: big/chip | P4: 0.0705
A5: 200859.INSI-26-192301 | B5: 22 | C5: 0.51 | D5: 1 | F5: 21 | G5: 15 | H5: 0.714 | I5: 0.0833 | J5: 0.5417 | K5: 0 | L5: 0.0417 | M5: 0 | N5: Full Rim | O5: small | P5: 0.5417
A6: 236095.IHR126B2C0000520 | B6: 53 | C6: 0.8 | D6: 1 | F6: 51 | G6: 11 | H6: 0.216 | I6: 0.1091 | J6: 0.0909 | K6: 0 | L6: 0.1273 | M6: 0 | N6: Full Rim | O6: big/scratch | P6: 0.1273
A7: 239316.IN026082901D | B7: 216 | C7: 1 | D7: 1 | F7: 212 | G7: 11 | H7: 0.052 | I7: 0.0423 | J7: 0.0047 | K7: 0.0047 | L7: 0.0376 | M7: 0.0047 | N7: Full Rim | O7: big | P7: 0.0423
A8: 242145.LSK26072101-A3 | B8: 35 | C8: 0.53 | D8: 1 | F8: 34 | G8: 11 | H8: 0.324 | I8: 0.0488 | J8: 0.0732 | K8: 0.0732 | L8: 0.0488 | M8: 0.0488 | N8: Full Rim | O8: small | P8: 0.0732
A9: 238757.26WLS-425K | B9: 89 | C9: 0.95 | D9: 1 | F9: 78 | G9: 10 | H9: 0.128 | I9: 0.0341 | J9: 0.0227 | K9: 0.0455 | L9: 0.1364 | M9: 0.0114 | N9: Full Rim | O9: scratch/big | P9: 0.1364
A10: 242221.IRJ127B2C0001909 | B10: 14 | C10: 0.33 | D10: 1 | F10: 15 | G10: 10 | H10: 0.667 | I10: 0 | J10: 0.5 | K10: 0 | L10: 0.1111 | M10: 0.0556 | N10: Full Rim | O10: small | P10: 0.5
A11: 207671.IHR127B2C0003243 | B11: 83 | C11: 0.04 | D11: 1 | F11: 85 | G11: 9 | H11: 0.106 | I11: 0.069 | J11: 0.023 | K11: 0.023 | L11: 0.092 | M11: 0 | N11: Full Rim | O11: big/scratch | P11: 0.092
A12: 234768.IRJ127B2C0002027 | B12: 26 | C12: 0.6 | D12: 1 | F12: 20 | G12: 9 | H12: 0.45 | I12: 0 | J12: 0.2963 | K12: 0.037 | L12: 0.037 | M12: 0.037 | N12: Full Rim | O12: small | P12: 0.2963
A13: 211292.FKS26336G | B13: 133 | C13: 0.96 | D13: 1 | F13: 131 | G13: 8 | H13: 0.061 | I13: 0.035 | J13: 0.007 | K13: 0.014 | L13: 0.035 | M13: 0 | N13: Full Rim | O13: big/scratch | P13: 0.035
... A39: 247078.IRJ127B2C0002446 | B39: 23 | C39: 0.85 | D39: 1 | F39: 22 | G39: 5 | H39: 0.227 | I39: 0.1304 | J39: 0 | K39: 0.087 | L39: 0.087 | M39: 0 | N39: Full Rim | O39: big | P39: 0.1304

Sheet Loose Fitting
A1: pid.invoice | B1: Sum of Count of barcode | C1: A | D1: B | E1: CIRC R | F1: CIRC L | G1: AFTER | H1: A1 | I1: B1 | J1: CIRC R1 | K1: CIRC L1 | L1: done by
A2: 150581.IN26029C | B2: 990 | C2: 55.35 | D2: 41.09 | E2: 163.89 | F2: 163.89 | G2: MANUAL | H2: 55.42 | I2: 41.57 | J2: 164.29 | K2: 164.16 | L2: ADITI
A3: 150581.IN26034H | B3: 600 | C3: 55.3 | D3: 40.58 | E3: 163.37 | F3: 163.59 | G3: MANUAL | H3: 55.47 | I3: 41.32 | J3: 164.58 | K3: 163.59 | L3: ADITI
A4: 150581.IN26039G | B4: 442 | C4: 55.36 | D4: 40.39 | E4: 164.3 | F4: 163.3 | G4: MANUAL | H4: 55.61 | I4: 41.1 | J4: 164.62 | K4: 164.03 | L4: ADITI
A5: 150581.IN26026G | B5: 311 | C5: 55.41 | D5: 40.64 | E5: 163.76 | F5: 164.09 | G5: MANUAL | H5: 55.51 | I5: 41.31 | J5: 164.71 | K5: 163.98 | L5: ADITI
A6: 150581.IN26011B | B6: 145 | C6: 55.6 | D6: 40.85 | E6: 165.19 | F6: 164.79 | G6: MANUAL | H6: 55.67 | I6: 41.19 | J6: 165.69 | K6: 164.82 | L6: ADITI
A7: 150581.IN26013E | B7: 123 | C7: 55.39 | D7: 40.76 | E7: 163.62 | F7: 163.62 | G7: MANUAL | H7: 55.5 | I7: 40.86 | J7: 163.69 | K7: 163.69 | L7: ADITI
A8: 150581 | B8: 108 | C8: SHAPE NOT PRESENT | L8: ADITI
A9: 150581.IN26034E | B9: 105 | C9: 55.19 | D9: 40.58 | E9: 163.27 | F9: 163.27 | G9: MANUAL | H9: 55.29 | I9: 40.68 | J9: 163.34 | K9: 163.95 | L9: ADITI
A10: 151703.FKS26175G | B10: 2002 | C10: 50.82 | D10: 43.38 | E10: 153.7 | F10: 153.7 | G10: MANUAL | H10: 50.92 | I10: 43.48 | J10: 153.95 | K10: 153.86 | L10: ADITI
A11: 151703.FKS26170A | B11: 1210 | C11: 50.62 | D11: 43.3 | E11: 153.3 | F11: 153.3 | G11: MANUAL | H11: 50.74 | I11: 43.41 | J11: 153.59 | K11: 153.63 | L11: ADITI
A12: 151703.FKS26308C | B12: 761 | C12: 50.42 | D12: 43.2 | E12: 154.07 | F12: 153.79 | G12: MANUAL | H12: 50.88 | I12: 43.5 | J12: 154.1 | K12: 155.09 | L12: ADITI
A13: 151703.FKS26285D | B13: 410 | C13: 50.86 | D13: 43.26 | E13: 153.97 | F13: 153.92 | G13: MANUAL | H13: 51 | I13: 43.46 | J13: 154.2 | K13: 154.07 | L13: ADITI
A14: 151703.FKS26199F | B14: 220 | C14: 50.95 | D14: 43.26 | E14: 154.54 | F14: 154.29 | G14: MANUAL | H14: 51.07 | I14: 43.63 | J14: 154.77 | K14: 155.1 | L14: ADITI
A15: 151703.FKS26154A | B15: 204 | C15: 50.61 | D15: 43.54 | E15: 154.09 | F15: 154 | G15: MANUAL | H15: 50.75 | I15: 43.64 | J15: 154.16 | K15: 154.16 | L15: ADITI
A16: 151703.FKS26154O | B16: 200 | C16: 50.6 | D16: 43.44 | E16: 153.98 | F16: 153.87 | G16: MANUAL | H16: 50.79 | I16: 43.54 | J16: 154.12 | K16: 154.27 | L16: ADITI
A17: 151703.FKS26119F | B17: 197 | C17: 50.66 | D17: 43.13 | E17: 153.53 | F17: 153.55 | G17: MANUAL | H17: 50.7 | I17: 43.45 | J17: 154.1 | K17: 153.47 | L17: ADITI
A18: 204392.LM2647C | B18: 1356 | C18: 44.38 | D18: 37.13 | E18: 131.41 | F18: 131.09 | G18: MANUAL | H18: 44.43 | I18: 37.17 | J18: 131.42 | K18: 131.14 | L18: ADITI
A19: 204392.LM2644A | B19: 352 | C19: 44.61 | D19: 37.16 | E19: 131.74 | F19: 132.11 | G19: MANUAL | H19: 44.62 | I19: 37.34 | J19: 132.08 | K19: 132.21 | L19: ADITI
A20: 204402.LM2647C | B20: 1440 | C20: 46.6 | D20: 35.67 | E20: 136.79 | F20: 136.87 | G20: MANUAL | H20: 46.65 | I20: 35.74 | J20: 136.84 | K20: 137.12 | L20: ADITI
... A26: 207481.IN26057C | B26: 2616 | C26: 50.7 | D26: 43.02 | E26: 153.73 | F26: 153.67 | G26: MANUAL | H26: 50.79 | I26: 43.07 | J26: 153.94 | K26: 153.75 | L26: ADITI
A27: 207481.IHR127B2C0003241 | B27: 603 | C27: SHAPE NOT PRESENT | L27: ADITI
A28: 207481.IHR127B2C0002955 | B28: 326 | C28: 51.14 | D28: 43.41 | E28: 155 | F28: 154.63 | G28: MANUAL | H28: 51.26 | I28: 43.52 | J28: 155.32 | K28: 154.99 | L28: ADITI
A29: 207481.IHR127B2C0003013 | B29: 317 | C29: 51.14 | D29: 43.4 | E29: 155 | F29: 154.71 | G29: MANUAL | H29: 51.25 | I29: 43.51 | J29: 155.33 | K29: 155.33 | L29: ADITI
A30: 207481.IHR127B2C0002083 | B30: 305 | C30: 50.91 | D30: 42.79 | E30: 154 | F30: 153.72 | G30: MANUAL | H30: 51.03 | I30: 42.9 | J30: 154.29 | K30: 154.29 | L30: ADITI
A31: 207481.IHR127B2C0003275 | B31: 300 | C31: SHAPE NOT PRESENT | L31: ADITI
A32: 207481.IHR127B2C0002069 | B32: 270 | C32: SHAPE NOT PRESENT | L32: ADITI
A33: 207481.IHR127B2C0003258 | B33: 268 | C33: 51.82 | D33: 43.69 | E33: 156.61 | F33: 156.07 | G33: MANUAL | H33: 51.93 | I33: 43.81 | J33: 156.93 | K33: 156.93 | L33: ADITI
A34: 207481.IHR127B2C0002998 | B34: 240 | C34: SHAPE NOT PRESENT | L34: ADITI
A35: 207481.IN26034L | B35: 217 | C35: 50.59 | D35: 43.07 | E35: 153.87 | F35: 153.75 | G35: MANUAL | H35: 50.79 | I35: 43.41 | J35: 154.27 | K35: 153.99 | L35: ADITI
A36: 207481.IHR127B2C0001885 | B36: 153 | C36: 50.78 | D36: 42.85 | E36: 153.86 | F36: 153.82 | G36: MANUAL | H36: 50.89 | I36: 42.96 | J36: 154.1 | K36: 154.1 | L36: ADITI
A37: 207481.IHR127B2C0001842 | B37: 141 | C37: SHAPE NOT PRESENT | L37: ADITI
A38: 207481.IHR127B2C0002092 | B38: 126 | C38: 50.61 | D38: 42.89 | E38: 153.59 | F38: 153.93 | G38: MANUAL | H38: 50.62 | I38: 42.89 | J38: 153.46 | K38: 155.07 | L38: ADITI
A39: 207481 | B39: 121 | C39: 51.26 | D39: 43.45 | E39: 155.51 | F39: 155.29 | G39: MANUAL | H39: 51.31 | I39: 43.51 | J39: 155.64 | K39: 155.45 | L39: ADITI
A40: 207481.IHR127B2C0001875 | B40: 98 | C40: 51.15 | D40: 43.01 | E40: 154.61 | F40: 154.61 | G40: MANUAL | H40: 51.25 | I40: 43.12 | J40: 154.96 | K40: 154.93 | L40: ADITI
A41: 207481.IHR127B2C0001190 | B41: 88 | C41: 50.64 | D41: 42.67 | E41: 153.38 | F41: 153.38 | G41: MANUAL | H41: 50.74 | I41: 42.77 | J41: 153.65 | K41: 153.65 | L41: ADITI
A42: 207481.IHR127B2C0001895 | B42: 85 | C42: SHAPE NOT PRESENT | L42: ADITI
A43: 218763.FKS26317H | B43: 2540 | C43: 52.2 | D43: 38.92 | E43: 152 | F43: 151.88 | G43: MANUAL | H43: 52.3 | I43: 38.92 | J43: 152.18 | K43: 152.18 | L43: ADITI
A44: 218763.FKS26325D | B44: 1598 | C44: SHAPE NOT PRESENT | L44: ADITI
A45: 218763.FKS26190O | B45: 819 | C45: 51.97 | D45: 38.71 | E45: 151.67 | F45: 151.58 | G45: MANUAL | H45: 52.05 | I45: 38.73 | J45: 151.73 | K45: 151.4 | L45: ADITI
...

Sheet 15-19 SEP
A1: frame_product_id | B1: vendor_invoice | C1: PID.INVOICE | D1: Total Items | E1: QC Done (DOT) | F1: MEI Fail (DOT) | G1: MEI Fail % (DOT) | H1: First frame_type | I1: BIG | J1: SMALL | K1: CHIP | L1: SCRATCH | M1: WRONG SHAPE | N1: ISSUE | O1: PERCENTAGE | P1: check1
A2: 241074 | B2: IRJ127B2C0002437 | C2: 241074.IRJ127B2C0002437 | D2: 11 | E2: 11 | F2: 6 | G2: 0.545 | H2: Full Rim | I2: 0.3077 | J2: 0.0769 | K2: 0.0769 | L2: 0.1538 | M2: 0 | N2: BIG | O2: 0.3077 | P2: =VLOOKUP(C:C,'Loose Fitting'!A:A,1,0) -> #N/A
A3: 234791 | B3: IRJ127B2C0002125 | C3: 234791.IRJ127B2C0002125 | D3: 121 | E3: 111 | F3: 33 | G3: 0.297 | H3: Full Rim | I3: 0.1812 | J3: 0.0671 | K3: 0 | L3: 0.0403 | M3: 0.0403 | N3: BIG | O3: 0.1812 | P3: =VLOOKUP(C:C,'Loose Fitting'!A:A,1,0) -> #N/A
A4: 247078 | B4: IRJ127B2C0002446 | C4: 247078.IRJ127B2C0002446 | D4: 25 | E4: 25 | F4: 7 | G4: 0.28 | H4: Full Rim | I4: 0.1667 | J4: 0.0333 | K4: 0.0333 | L4: 0.0667 | M4: 0 | N4: BIG | O4: 0.1667 | P4: =VLOOKUP(C:C,'Loose Fitting'!A:A,1,0) -> #N/A
A5: 236092 | B5: IHR127B2C0001880 | C5: 236092.IHR127B2C0001880 | D5: 40 | E5: 40 | F5: 6 | G5: 0.15 | H5: Full Rim | I5: 0.0976 | J5: 0.0488 | K5: 0 | L5: 0.0244 | M5: 0 | N5: BIG | O5: 0.0976 | P5: =VLOOKUP(C:C,'Loose Fitting'!A:A,1,0) -> #N/A
A6: 234791 | B6: IRJ127B2C0001934 | C6: 234791.IRJ127B2C0001934 | D6: 39 | E6: 41 | F6: 5 | G6: 0.122 | H6: Full Rim | I6: 0.0909 | J6: 0 | K6: 0.0227 | L6: 0 | M6: 0.0227 | N6: BIG | O6: 0.0909 | P6: =VLOOKUP(C:C,'Loose Fitting'!A:A,1,0) -> #N/A
A7: 241117 | B7: IRJ127B2C0002503 | C7: 241117.IRJ127B2C0002503 | D7: 61 | E7: 57 | F7: 7 | G7: 0.123 | H7: Full Rim | I7: 0.0678 | J7: 0.0169 | K7: 0.0169 | L7: 0.0508 | M7: 0.0169 | N7: BIG | O7: 0.0678 | P7: =VLOOKUP(C:C,'Loose Fitting'!A:A,1,0) -> #N/A
A8: 217079 | B8: LSK26082501-A7 | C8: 217079.LSK26082501-A7 | D8: 149 | E8: 144 | F8: 8 | G8: 0.056 | H8: Full Rim | I8: 0.0411 | J8: 0 | K8: 0.0068 | L8: 0.0342 | M8: 0.0068 | N8: BIG | O8: 0.0411 | P8: =VLOOKUP(C:C,'Loose Fitting'!A:A,1,0) -> #N/A
A9: 222280 | B9: 26L160C | C9: 222280.26L160C | D9: 76 | E9: 81 | F9: 5 | G9: 0.062 | H9: Full Rim | I9: 0.0361 | J9: 0 | K9: 0 | L9: 0.012 | M9: 0.0241 | N9: BIG | O9: 0.0361 | P9: =VLOOKUP(C:C,'Loose Fitting'!A:A,1,0) -> #N/A
A10: 137971 | B10: FKS26228F | C10: 137971.FKS26228F | D10: 119 | E10: 122 | F10: 9 | G10: 0.074 | H10: Full Rim | I10: 0.0391 | J10: 0.0313 | K10: 0.0156 | L10: 0.0469 | M10: 0 | N10: BIG /SCRATCH | O10: 0.0469 | P10: =VLOOKUP(C:C,'Loose Fitting'!A:A,1,0) -> #N/A
A11: 222280 | B11: 26L160B | C11: 222280.26L160B | D11: 65 | E11: 67 | F11: 8 | G11: 0.119 | H11: Full Rim | I11: 0.0857 | J11: 0 | K11: 0.0143 | L11: 0.0857 | M11: 0.0143 | N11: BIG/SCRATCH | O11: 0.0857 | P11: =VLOOKUP(C:C,'Loose Fitting'!A:A,1,0) -> #N/A
A12: 241089 | B12: IRJ127B2C0001744 | C12: 241089.IRJ127B2C0001744 | D12: 114 | E12: 106 | F12: 15 | G12: 0.142 | H12: Full Rim | I12: 0.0796 | J12: 0 | K12: 0.0708 | L12: 0.0973 | M12: 0 | N12: BIG/SCRATCH | O12: 0.0973 | P12: =VLOOKUP(C:C,'Loose Fitting'!A:A,1,0) -> #N/A
A13: 222135 | B13: KC078260616 | C13: 222135.KC078260616 | D13: 91 | E13: 90 | F13: 5 | G13: 0.056 | H13: Full Rim | I13: 0.0222 | J13: 0.0111 | K13: 0.0111 | L13: 0.0222 | M13: 0.0111 | N13: BIG/SCRATCH | O13: 0.0222 | P13: =VLOOKUP(C:C,'Loose Fitting'!A:A,1,0) -> #N/A
... A37: 244798 | B37: 26WLS-331B | C37: 244798.26WLS-331B | D37: 14 | E37: 13 | F37: 10 | G37: 0.769 | H37: Full Rim | I37: 0.1111 | J37: 0.0556 | K37: 0.0556 | L37: 0.1111 | M37: 0.3889 | N37: WRONG SHAPE | O37: 0.3889 | P37: =VLOOKUP(C:C,'Loose Fitting'!A:A,1,0) -> #N/A

Sheet 12-14 SEP
A1: PID.INVOICE | B1: Total Items | C1: QC Done (DOT) | D1: MEI Fail (DOT) | E1: MEI Fail % (DOT) | F1: First frame_type | G1: BIG | H1: SMALL | I1: CHIP | J1: WRONG SHAPE | K1: SCRATCH | L1: ISSUE | M1: PERCENTAGE
A2: 241186.IN26056C | B2: 19 | C2: 16 | D2: 3 | E2: 0.188 | F2: Full Rim | G2: 0.1875 | H2: 0 | I2: 0 | J2: 0 | K2: 0.0625 | L2: BIG | M2: 0.1875
A3: 206728.FKS26191E | B3: 43 | C3: 41 | D3: 6 | E3: 0.146 | F3: Full Rim | G3: 0.119 | H3: 0 | I3: 0.0238 | J3: 0 | K3: 0.0952 | L3: BIG | M3: 0.119
A4: 245911.FKS26218I | B4: 54 | C4: 52 | D4: 5 | E4: 0.096 | F4: Full Rim | G4: 0.0962 | H4: 0 | I4: 0 | J4: 0 | K4: 0.0385 | L4: BIG | M4: 0.0962
A5: 221172.FKS26304A | B5: 53 | C5: 52 | D5: 5 | E5: 0.096 | F5: Full Rim | G5: 0.0943 | H5: 0 | I5: 0 | J5: 0 | K5: 0.0189 | L5: BIG | M5: 0.0943
A6: 246865.FKS26210F | B6: 32 | C6: 31 | D6: 3 | E6: 0.097 | F6: Full Rim | G6: 0.0909 | H6: 0 | I6: 0 | J6: 0 | K6: 0.0606 | L6: BIG | M6: 0.0909
A7: 217659.FKS26190E | B7: 52 | C7: 53 | D7: 3 | E7: 0.057 | F7: Full Rim | G7: 0.0566 | H7: 0 | I7: 0 | J7: 0 | K7: 0.0377 | L7: BIG | M7: 0.0566
A8: 241185.IN26054E | B8: 38 | C8: 37 | D8: 4 | E8: 0.108 | F8: Full Rim | G8: 0.0541 | H8: 0.027 | I8: 0.027 | J8: 0 | K8: 0 | L8: BIG | M8: 0.0541
A9: 239021.FKS26323A | B9: 79 | C9: 79 | D9: 4 | E9: 0.051 | F9: Full Rim | G9: 0.038 | H9: 0 | I9: 0.0127 | J9: 0 | K9: 0.0253 | L9: BIG | M9: 0.038
A10: 211293.FKS26182D | B10: 55 | C10: 52 | D10: 3 | E10: 0.058 | F10: Full Rim | G10: 0.037 | H10: 0 | I10: 0.0185 | J10: 0 | K10: 0 | L10: BIG | M10: 0.037
A11: 241112.IRJ127B2C0002302 | B11: 28 | C11: 28 | D11: 3 | E11: 0.107 | F11: Full Rim | G11: 0.0714 | H11: 0 | I11: 0.0714 | J11: 0 | K11: 0 | L11: BIG/CHIP | M11: 0.0714
A12: 241100.IRJ127B2C0002100 | B12: 64 | C12: 61 | D12: 4 | E12: 0.066 | F12: Full Rim | G12: 0.0625 | H12: 0 | I12: 0.0313 | J12: 0 | K12: 0.0625 | L12: BIG/SCRATCH | M12: 0.0625
A13: 241124.IRJ127B2C0002671 | B13: 49 | C13: 47 | D13: 3 | E13: 0.064 | F13: Full Rim | G13: 0.0417 | H13: 0 | I13: 0 | J13: 0.0208 | K13: 0.0417 | L13: BIG/SCRATCH | M13: 0.0417
... A22: 206775.WMW26YFS0128A | B22: 22 | C22: 23 | D22: 3 | E22: 0.13 | F22: Full Rim | G22: 0 | H22: 0.1304 | I22: 0 | J22: 0 | K22: 0.0435 | L22: SMALL | M22: 0.1304

Sheet SHAPE 10-12 SEP
A1: PID.INVOICE | B1: Total Items | C1: QC Done (DOT) | D1: MEI Fail (DOT) | E1: MEI Fail % (DOT) | F1: First frame_type | G1: ISSUE | H1: PERCENTAGE
A2: 245915.FKS26272 | B2: 7 | C2: 9 | D2: 4 | E2: 0.444 | F2: Full Rim | G2: BIG | H2: 0.0972
A3: 241094.IRJ127B2C0002470 | B3: 26 | C3: 23 | D3: 6 | E3: 0.261 | F3: Full Rim | G3: BIG | H3: 0.16
A4: 234791.IRJ127B2C0001913 | B4: 42 | C4: 38 | D4: 9 | E4: 0.237 | F4: Full Rim | G4: BIG | H4: 0.1333
A5: 247138.FKS26245 | B5: 56 | C5: 54 | D5: 5 | E5: 0.093 | F5: Full Rim | G5: BIG | H5: 0.0556
A6: 206728.FKS26197H | B6: 66 | C6: 62 | D6: 4 | E6: 0.065 | F6: Full Rim | G6: BIG | H6: 0.0476
A7: 137934.FS2619C | B7: 71 | C7: 65 | D7: 4 | E7: 0.062 | F7: Full Rim | G7: BIG | H7: 0.0448
A8: 240785.FKS26297A | B8: 65 | C8: 65 | D8: 4 | E8: 0.062 | F8: Full Rim | G8: BIG | H8: 0.0615
A9: 210433.FKS26197T | B9: 106 | C9: 102 | D9: 6 | E9: 0.059 | F9: Full Rim | G9: BIG | H9: 0.049
A10: 240000.IN026071404E | B10: 9 | C10: 8 | D10: 6 | E10: 0.75 | F10: Full Rim | G10: BIG/CHIP | H10: 0.3333
A11: 245915.FKS26272 | B11: 72 | C11: 71 | D11: 14 | E11: 0.197 | F11: Full Rim | G11: BIG/CHIP | H11: 0.0972
A12: 241093.IRJ127B2C0002248 | B12: 27 | C12: 28 | D12: 4 | E12: 0.143 | F12: Full Rim | G12: BIG/SCRATCH | H12: 0.129
A13: 236141.26L123F | B13: 93 | C13: 88 | D13: 5 | E13: 0.057 | F13: Full Rim | G13: BIG/SCRATCH | H13: 0.0444
... A26: 231612.IN26054P | B26: 37 | C26: 36 | D26: 4 | E26: 0.111 | F26: Full Rim | G26: WRONG SHAPE | H26: 0.0541

Sheet daily report
A1: PID.INVOICE
A2: 242206.26WLS-310C | B2: 219545.FKS26200O
A3: 239839.CIN-000001218048 | B3: 146653.F2604A
A4: 225336.IRJ127B2C0000270 | B4: 246227.LSK26070801-A3
A5: 239999.IN026062202D | B5: 148524.FKS26186J
A6: 238757.26WLS-313B | B6: 221282.LSK26062202-A3
A7: 239839.CIN-000001093608 | B7: 241113.IRJ127B2C0001389
A8: 246233.LSK26060502-A12 | B8: 210433.FKS26197T
A9: 234769.IRJ127B2C0001392 | B9: 210433.FKS26198O
A10: 227035.26Y079 | B10: 241854.IN26045F
A11: 241119.IRJ127B2C0001558 | B11: 241124.IRJ127B2C0001634
A12: 234804.IRJ127B2C0001660 | B12: 241089.IRJ127B2C0001689
A13: 241117.IRJ127B2C0001436 | B13: 137971.FKS26223B
... A18: 239839.CIN-000001093608 | B18: 213182.LSK26062202-A7
A19: 234791 | B19: 146622.26WLS-332E
A20: 206775.WMW26YFS0128D | B20: 241119.IRJ127B2C0001593

Sheet Sheet32

Sheet IMPORTANT
A2: FAIL REASON | B2: PID | C2: PID.INVOICE | D2: FAIL COUNT | E2: status
A3: SMALL SIZE | B3: 228743 | C3: 228743.26YC063B | D3: 92 | E3: =VLOOKUP(C3,'14-18 JULY'!C:C,1,0) -> #N/A
A4: SMALL SIZE | B4: 228743 | C4: 228743.26YC063 | D4: 76 | E4: =VLOOKUP(C4,'14-18 JULY'!C:C,1,0) -> #N/A
A5: SMALL SIZE | B5: 228743 | C5: 228743.26YC049 | D5: 50 | E5: DONE
A6: SMALL SIZE | B6: 228743 | C6: 228743.26YC064B | D6: 31 | E6: =VLOOKUP(C6,'14-18 JULY'!C:C,1,0) -> #N/A
A7: SMALL SIZE | B7: 234796 | C7: 234796.CIN-000001462531 | D7: 193 | E7: DONE
A8: SMALL SIZE | B8: 234796 | C8: 234796.IRJ126B2C0001235 | D8: 106 | E8: DONE
A9: SMALL SIZE | B9: 234796 | C9: 234796.CIN-000001467074 | D9: 80 | E9: DONE
A10: SMALL SIZE | B10: 220126 | C10: 220126.H2630 | D10: 106 | E10: DONE
A11: SMALL SIZE | B11: 220126 | C11: 220126.H2628B | D11: 54 | E11: =VLOOKUP(C11,'14-18 JULY'!C:C,1,0) -> #N/A
A12: SMALL SIZE | B12: 225336 | C12: 225336.IRJ127B2C0000270 | D12: 127 | E12: =VLOOKUP(C12,'14-18 JULY'!C:C,1,0) -> #N/A
A13: SMALL SIZE | B13: 225336 | C13: 225336.IRJ126B2C0003378 | D13: 44 | E13: =VLOOKUP(C13,'14-18 JULY'!C:C,1,0) -> #N/A
A14: SMALL SIZE | B14: 225336 | C14: 225336.IRJ126B2C0001387 | D14: 35 | E14: DONE
A15: SMALL SIZE | B15: 225336 | C15: 225336.IRJ127B2C0000223 | D15: 33 | E15: DONE
A16: SMALL SIZE | B16: 234797 | C16: 234797.IRJ127B2C0000394 | D16: 36 | E16: =VLOOKUP(C16,'14-18 JULY'!C:C,1,0) -> #N/A
A17: SMALL SIZE | B17: 234797 | C17: 234797.IRJ127B2C0000958 | D17: 29 | E17: =VLOOKUP(C17,'14-18 JULY'!C:C,1,0) -> #N/A
A18: SMALL SIZE | B18: 243271 | C18: 243271.LSK26060502-A8 | D18: 91 | E18: =VLOOKUP(C18,'14-18 JULY'!C:C,1,0) -> #N/A
A19: SMALL SIZE | B19: 219825 | C19: 219825.LSK26060502-A15 | D19: 136 | E19: DONE
A20: SMALL SIZE | B20: 219825 | C20: 219825.LSK20260521-A3 | D20: 26 | E20: =VLOOKUP(C20,'14-18 JULY'!C:C,1,0) -> #N/A
A21: SMALL SIZE | B21: 241097 | C21: 241097.IRJ127B2C0001064 | D21: 54 | E21: =VLOOKUP(C21,'14-18 JULY'!C:C,1,0) -> #N/A
A22: SMALL SIZE | B22: 201272 | C22: 201272.FKS26098A | D22: 145 | E22: =VLOOKUP(C22,'14-18 JULY'!C:C,1,0) -> #N/A
A23: SMALL SIZE | B23: 201272 | C23: 201272.SLK260409E | D23: 38 | E23: =VLOOKUP(C23,'14-18 JULY'!C:C,1,0) -> #N/A
A24: SMALL SIZE | B24: 241112 | C24: 241112.IRJ127B2C000801 | D24: 12 | E24: =VLOOKUP(C24,'14-18 JULY'!C:C,1,0) -> #N/A
A25: SMALL SIZE | B25: 241112 | C25: 241112.IRJ127B2C0000715 | D25: 6 | E25: =VLOOKUP(C25,'14-18 JULY'!C:C,1,0) -> #N/A
A26: SMALL SIZE | B26: 241112 | C26: 241112.IRJ127B2C0000829 | D26: 5 | E26: =VLOOKUP(C26,'14-18 JULY'!C:C,1,0) -> #N/A
A27: SMALL SIZE | B27: 241112 | C27: 241112.IRJ127B2C000797 | D27: 4 | E27: =VLOOKUP(C27,'14-18 JULY'!C:C,1,0) -> #N/A
A28: SMALL SIZE | B28: 241112 | C28: 241112.IRJ127B2C0001028 | D28: 4 | E28: =VLOOKUP(C28,'14-18 JULY'!C:C,1,0) -> #N/A
A29: SMALL SIZE | B29: 217873 | C29: 217873.263053-E | D29: 41 | E29: =VLOOKUP(C29,'14-18 JULY'!C:C,1,0) -> #N/A
A30: SMALL SIZE | B30: 217873 | C30: 217873.263052-G | D30: 39 | E30: =VLOOKUP(C30,'14-18 JULY'!C:C,1,0) -> #N/A
A31: SMALL SIZE | B31: 217873 | C31: 217873.263058-G | D31: 38 | E31: =VLOOKUP(C31,'14-18 JULY'!C:C,1,0) -> #N/A
... A51: SMALL SIZE | B51: 234793 | C51: 234793.IRJ127B2C0000608 | D51: 6 | E51: =VLOOKUP(C51,'14-18 JULY'!C:C,1,0) -> #N/A
A52: SMALL SIZE | B52: 218966 | C52: 218966.IRJ127B2C000807 | D52: 36 | E52: DONE
A53: SMALL SIZE | B53: 218966 | C53: 218966.IRJ127B2C0000380 | D53: 9 | E53: =VLOOKUP(C53,'14-18 JULY'!C:C,1,0) -> #N/A
A54: SMALL SIZE | B54: 218966 | C54: 218966.IRJ127B2C0000086 | D54: 8 | E54: =VLOOKUP(C54,'14-18 JULY'!C:C,1,0) -> #N/A
A55: SMALL SIZE | B55: 227606 | C55: 227606.26Y086 | D55: 287 | E55: =VLOOKUP(C55,'14-18 JULY'!C:C,1,0) -> #N/A
A56: SMALL SIZE | B56: 227606 | C56: 227606.26Y071 | D56: 28 | E56: =VLOOKUP(C56,'14-18 JULY'!C:C,1,0) -> #N/A
A57: SMALL SIZE | B57: 227606 | C57: 227606.26Y087 | D57: 10 | E57: =VLOOKUP(C57,'14-18 JULY'!C:C,1,0) -> #N/A
A58: SMALL SIZE | B58: 218222 | C58: 218222.IHR127B2C0002800 | D58: 10 | E58: =VLOOKUP(C58,'14-18 JULY'!C:C,1,0) -> #N/A
A59: SMALL SIZE | B59: 218222 | C59: 218222.CIN-000001075510 | D59: 4 | E59: =VLOOKUP(C59,'14-18 JULY'!C:C,1,0) -> #N/A
A60: SMALL SIZE | B60: 220577 | C60: 220577.H2629 | D60: 70 | E60: =VLOOKUP(C60,'14-18 JULY'!C:C,1,0) -> #N/A
...

Sheet JUNE ANALYSIS SUMMARY
A3: COLOUR CODE LEGEND
A4: 🔴 RED | B4: MEI Fail% HIGHER than May reference – Critical attention needed
A5: 🟡 YELLOW | B5: MEI Fail% SLIGHTLY INCREASED compared to May – Monitor closely
A6: 🩷 PINK | B6: MEI Fail% DECREASED (Good improvement) vs May reference
A7: 🟢 GREEN | B7: NEW PID/Invoice – Not present in May reference data
A11: Total PIDs Analysed | C11: RED – Higher MEI Fail% | E11: YELLOW – Slight Increase | G11: PINK – Good Decrease | I11: GREEN – New PID/Invoice
A12: 97 | C12: 12 | E12: 9 | G12: 22 | I12: 54
A14: CLASSIFICATION BREAKDOWN BY SHEET
A15: Sheet Period | B15: RED | C15: YELLOW | D15: PINK | E15: GREEN | F15: Total
A16: 1-10 jUNE | B16: 7 | C16: 5 | D16: 8 | E16: 25 | F16: 45
A17: 17-20 JUNE | B17: 2 | C17: 3 | D17: 9 | E17: 15 | F17: 29
A18: 20-24 JUNE | B18: 3 | C18: 1 | D18: 5 | E18: 14 | F18: 23
A19: TOTAL | B19: 12 | C19: 9 | D19: 22 | E19: 54 | F19: 97
A21: 🔴 RED: HIGH RISK – MEI Fail% INCREASED vs May Reference
A22: PID.INVOICE | B22: Sheet Period | C22: Issue | D22: Issue % | E22: Jun MEI Fail% | F22: May MEI Fail% | G22: Δ Change | H22: MEI Fail (DOT) | I22: QC Done | J22: Frame PID | K22: Invoice
A23: 234798.CIN-000001389050 | B23: 17-20 June | E23: 0.8 | F23: 0.248 | G23: =+55.2% -> 0.552 | H23: 4 | I23: 5 | J23: 234798 | K23: CIN-000001389050
A24: 236095.IHR127B2C0000567 | B24: 1-10 June | C24: SMALL | D24: 0.113 | E24: 0.636 | F24: 0.182 | G24: =+45.4% -> 0.454 | H24: 7 | I24: 11 | J24: 236095 | K24: IHR127B2C0000567
A25: 236095.IHR127B2C0000387 | B25: 20-24 June | E25: 0.556 | F25: 0.182 | G25: =+37.4% -> 0.374 | H25: 5 | I25: 9 | J25: 236095 | K25: IHR127B2C0000387
A26: 134949.IN026042005C | B26: 20-24 June | C26: SMALL | D26: 24 | E26: 0.5 | F26: 0.441 | G26: =+5.9% -> 0.059 | H26: 9 | I26: 18 | J26: 134949 | K26: IN026042005C
A27: 236095.IHR126B2C0001613 | B27: 1-10 June | C27: SMALL | D27: 0.313 | E27: 0.344 | F27: 0.182 | G27: =+16.2% -> 0.162 | H27: 11 | I27: 32 | J27: 236095 | K27: IHR126B2C0001613
A28: 234792.CIN-000001885518 | B28: 1-10 June | C28: SMALL | D28: 0.258 | E28: 0.289 | F28: 0.214 | G28: =+7.5% -> 0.075 | H28: 24 | I28: 83 | J28: 234792 | K28: CIN-000001885518
A29: 236095.IHR127B2C0000582 | B29: 1-10 June | C29: BIG | D29: 0.178 | E29: 0.232 | F29: 0.182 | G29: =+5% -> 0.05 | H29: 44 | I29: 190 | J29: 236095 | K29: IHR127B2C0000582
A30: 134951.IN026051603H | B30: 1-10 June | C30: SMALL | D30: 0.048 | E30: 0.222 | F30: 0.154 | G30: =+6.8% -> 0.068 | H30: 32 | I30: 144 | J30: 134951 | K30: IN026051603H
A31: 239839.CIN-000001839710 | B31: 1-10 June | C31: BIG | D31: 0.098 | E31: 0.196 | F31: 0.105 | G31: =+9.1% -> 0.091 | H31: 10 | I31: 51 | J31: 239839 | K31: CIN-000001839710
A32: 217873.263053-E | B32: 17-20 June | C32: BIG | D32: 0.064 | E32: 0.196 | F32: 0.063 | G32: =+13.3% -> 0.133 | H32: 10 | I32: 51 | J32: 217873 | K32: 263053-E
A33: 221282.LSK20260516-A4 | B33: 1-10 June | C33: BIG | D33: 0.136 | E33: 0.184 | F33: 0.12 | G33: =+6.4% -> 0.064 | H33: 41 | I33: 223 | J33: 221282 | K33: LSK20260516-A4
A34: 217873.263053-E | B34: 20-24 June | E34: 0.154 | F34: 0.063 | G34: =+9.1% -> 0.091 | H34: 6 | I34: 39 | J34: 217873 | K34: 263053-E
A37: 🩷 PINK: IMPROVED – MEI Fail% DECREASED vs May Reference
A38: PID.INVOICE | B38: Sheet Period | C38: Issue | D38: Issue % | E38: Jun MEI Fail% | F38: May MEI Fail% | G38: Δ Change | H38: MEI Fail (DOT) | I38: QC Done | J38: Frame PID | K38: Invoice
A39: 219829.LSK20260528-A1 | B39: 20-24 June | E39: 0.051 | F39: 0.152 | G39: -0.101 | H39: 5 | I39: 98 | J39: 219829 | K39: LSK20260528-A1
A40: 215983.CL2026012C | B40: 17-20 June | C40: BIG | D40: 0.027 | E40: 0.055 | F40: 0.092 | G40: -0.037 | H40: 6 | I40: 110 | J40: 215983 | K40: CL2026012C
A41: 137971.FKS26124C | B41: 20-24 June | C41: BIG | D41: 2.5 | E41: 0.056 | F41: 0.07 | G41: -0.014 | H41: 6 | I41: 108 | J41: 137971 | K41: FKS26124C
A42: 137971.FKS26098 | B42: 1-10 June | C42: BIG | D42: 0.03 | E42: 0.057 | F42: 0.07 | G42: -0.013 | H42: 7 | I42: 123 | J42: 137971 | K42: FKS26098
A43: 211307.FS2604B | B43: 1-10 June | C43: BIG | D43: 0.024 | E43: 0.065 | F43: 0.154 | G43: -0.089 | H43: 8 | I43: 123 | J43: 211307 | K43: FS2604B
A44: 223230.263046-B | B44: 1-10 June | C44: BIG | D44: 0.031 | E44: 0.066 | F44: 0.063 | G44: =+0.3% -> 0.003 | H44: 12 | I44: 183 | J44: 223230 | K44: 263046-B
A45: 211307.FS2609 | B45: 20-24 June | C45: SMALL | D45: 7.2 | E45: 0.069 | F45: 0.154 | G45: -0.085 | H45: 14 | I45: 202 | J45: 211307 | K45: FS2609
A46: 148157.26WLS-209O | B46: 17-20 June | C46: BIG | D46: 0.061 | E46: 0.07 | F46: 0.066 | G46: =+0.4% -> 0.004 | H46: 5 | I46: 71 | J46: 148157 | K46: 26WLS-209O
A47: 148157.26WLS-209O | B47: 20-24 June | C47: BIG | D47: 3.6 | E47: 0.073 | F47: 0.066 | G47: =+0.7% -> 0.007 | H47: 6 | I47: 82 | J47: 148157 | K47: 26WLS-209O
A48: 211307.FS2604 | B48: 1-10 June | C48: BIG | D48: 0.077 | E48: 0.094 | F48: 0.095 | G48: -0.001 | H48: 11 | I48: 117 | J48: 211307 | K48: FS2604
A49: 211307.FS2609 | B49: 17-20 June | C49: SMALL | D49: 0.095 | E49: 0.095 | F49: 0.154 | G49: -0.059 | H49: 13 | I49: 137 | J49: 211307 | K49: FS2609
...

Sheet 20-25 May
A1: FRAME PID | B1: INVOICE | C1: PID.INVOICE | D1: QC Done (DOT) | E1: MEI Fail (DOT) | F1: MEI Fail % (DOT) | G1: ISSUE | H1: PERCENTAGE | I1: A | J1: B | K1: CIRC R | L1: CIRC L | M1: AFTER | N1: A1 | O1: B1 | P1: CIRC R1 | Q1: CIRC L1 | R1: DONE BY | S1: Frame Type
A2: 134949 | B2: IN026042005C | C2: 134949.IN026042005C | D2: 34 | E2: 15 | F2: 0.441 | G2: BIG | H2: 9.6 | R2: Aditi | S2: Full Rim
A3: 134951 | B3: IN026042503B | C3: 134951.IN026042503B | D3: 65 | E3: 10 | F3: 0.154 | G3: BIG | H3: 3.7 | R3: Aditi | S3: Full Rim
A4: 219834 | B4: LSK20260310-A5 | C4: 219834.LSK20260310-A5 | D4: 45 | E4: 9 | F4: 0.2 | G4: BIG | H4: 6 | I4: 53.76 | J4: 39.85 | K4: 159.2 | L4: 159.21 | N4: 53.7 | O4: 39.8 | P4: 159.2 | Q4: 159.21 | R4: Aditi | S4: Full Rim
A5: 240555 | B5: LSK20260427-A8 | C5: 240555.LSK20260427-A8 | D5: 33 | E5: 9 | F5: 0.273 | G5: BIG | H5: 25.9 | I5: 49.62 | J5: 40.99 | K5: 147.67 | L5: 147.81 | N5: 49.42 | O5: 40.95 | P5: 147.67 | Q5: 147.81 | R5: Aditi | S5: Full Rim
A6: 207991 | B6: CIN-000001690737 | C6: 207991.CIN-000001690737 | D6: 68 | E6: 7 | F6: 0.103 | G6: SMALL | H6: 5.6 | I6: 52.44 | J6: 38.19 | K6: 154.66 | L6: 154.44 | N6: 52.5 | O6: 38.25 | P6: 154.66 | Q6: 154.44 | R6: Aditi | S6: Full Rim
A7: 207991 | B7: CIN-000001732589 | C7: 207991.CIN-000001732589 | D7: 62 | E7: 7 | F7: 0.113 | G7: BIG | H7: 8.5 | I7: 53.38 | J7: 39.23 | K7: 158.07 | L7: 157.86 | N7: 53.44 | O7: 39.29 | P7: 158.07 | Q7: 157.86 | R7: Aditi | S7: Full Rim
A8: 215983 | B8: CL2026008B | C8: 215983.CL2026008B | D8: 76 | E8: 7 | F8: 0.092 | G8: CHIP | H8: 6.82 | I8: 51.02 | J8: 39.9 | K8: 153.29 | L8: 153.23 | N8: 51.05 | O8: 39.98 | P8: 153.29 | Q8: 153.23 | R8: Aditi | S8: Full Rim
A9: 241123 | B9: IRJ127B2C0000249 | C9: 241123.IRJ127B2C0000249 | D9: 21 | E9: 7 | F9: 0.333 | G9: BIG | H9: 20 | I9: 53.44 | J9: 50.68 | K9: 165.15 | L9: 166.64 | N9: 54.22 | O9: 50.1 | P9: 165.15 | Q9: 166.64 | R9: Aditi | S9: Full Rim
A10: 201272 | B10: FKS26132A | C10: 201272.FKS26132A | D10: 58 | E10: 6 | F10: 0.103 | G10: BIG | H10: 11.5 | I10: 57.69 | J10: 46.62 | K10: 173.92 | L10: 173.73 | N10: 57.61 | O10: 46.04 | P10: 173.92 | Q10: 173.73 | R10: Aditi | S10: Full Rim
A11: 211307 | B11: FS2604B | C11: 211307.FS2604B | D11: 39 | E11: 6 | F11: 0.154 | G11: BIG | H11: 11.8 | I11: 53.45 | J11: 37.95 | K11: 147.68 | L11: 147.68 | N11: 53.4 | O11: 37.9 | P11: 147.68 | Q11: 147.68 | R11: Aditi | S11: Full Rim
A12: 219834 | B12: LSK20260310-A2 | C12: 219834.LSK20260310-A2 | D12: 64 | E12: 6 | F12: 0.094 | G12: BIG | H12: 6 | I12: 53.72 | J12: 39.51 | K12: 159.4 | L12: 159.37 | N12: 53.66 | O12: 39.46 | P12: 159.4 | Q12: 159.37 | R12: Aditi | S12: Full Rim
A13: 223230 | B13: 263046-B | C13: 223230.263046-B | D13: 95 | E13: 6 | F13: 0.063 | G13: BIG | H13: 4.1 | I13: 48.15 | J13: 42.04 | K13: 145.02 | L13: 144.82 | N13: 48.08 | O13: 41.96 | P13: 145.02 | Q13: 144.82 | R13: Aditi | S13: Full Rim
A14: 234765 | B14: CIN-000001885501 | C14: 234765.CIN-000001885501 | D14: 13 | E14: 6 | F14: 0.462 | G14: SMALL | H14: 39.1 | I14: 54.86 | J14: 38.66 | K14: 160.24 | L14: 159.8 | N14: 55.07 | O14: 38.93 | P14: 160.24 | Q14: 159.8 | R14: Aditi | S14: Full Rim
A15: 238829 | B15: IRJ127B2C0000208 | C15: 238829.IRJ127B2C0000208 | D15: 88 | E15: 6 | F15: 0.068 | G15: SCRATCH | H15: 8.33 | R15: Aditi | S15: Rimless
A16: 238846 | B16: FKS26088N | C16: 238846.FKS26088N | D16: 74 | E16: 6 | F16: 0.081 | G16: BIG | H16: 3.3 | I16: 51.47 | J16: 40.4 | K16: 152.38 | L16: 152.41 | N16: 51.42 | O16: 40.36 | P16: 152.38 | Q16: 152.41 | R16: Aditi | S16: Full Rim
A17: 134949 | B17: IN026042504D | C17: 134949.IN026042504D | D17: 7 | E17: 5 | F17: 0.714 | G17: BIG,CHIP | H17: 20,60 | I17: 56.32 | J17: 45.46 | K17: 170.05 | L17: 170.05 | N17: 56.26 | O17: 45.4 | P17: 170.05 | Q17: 170.05 | R17: Aditi | S17: Full Rim
A18: 146617 | B18: 26WLS-175D | C18: 146617.26WLS-175D | D18: 83 | E18: 5 | F18: 0.06 | G18: BIG | H18: 2.6 | I18: 52.13 | J18: 43.57 | K18: 154.73 | L18: 154.73 | N18: 52.11 | O18: 43.42 | P18: 154.73 | Q18: 154.73 | R18: Aditi | S18: Full Rim
A19: 224842 | B19: 263052-B | C19: 224842.263052-B | D19: 61 | E19: 5 | F19: 0.082 | G19: BIG | H19: 5.4 | I19: 49.81 | J19: 46.19 | K19: 154.4 | L19: 154.45 | N19: 49.75 | O19: 46.13 | P19: 154.4 | Q19: 154.45 | R19: Aditi | S19: Full Rim
A20: 234785 | B20: IRJ127B2C0000361 | C20: 234785.IRJ127B2C0000361 | D20: 46 | E20: 5 | F20: 0.109 | G20: SMALL | H20: 3.6 | I20: 52.12 | J20: 40.48 | K20: 153.22 | L20: 153.55 | N20: 52.32 | O20: 40.68 | P20: 153.22 | Q20: 153.55 | R20: Aditi | S20: Full Rim
A21: 240781 | B21: FKS26099C | C21: 240781.FKS26099C | D21: 93 | E21: 5 | F21: 0.054 | G21: BIG | H21: 4.7 | I21: 55.43 | J21: 35.48 | K21: 158.52 | L21: 158.49 | N21: 55.37 | O21: 35.4 | P21: 158.52 | Q21: 158.49 | R21: Aditi | S21: Full Rim
A22: 242246 | B22: KC078260326C | C22: 242246.KC078260326C | D22: 91 | E22: 5 | F22: 0.055 | G22: BIG | H22: 3.7 | I22: 49.81 | J22: 44.54 | K22: 150.26 | L22: 150.25 | N22: 49.67 | O22: 44.44 | P22: 150.26 | Q22: 150.25 | R22: Aditi | S22: Full Rim
A23: 217873 | B23: 263052-G | C23: 217873.263052-G | D23: 63 | E23: 4 | F23: 0.063 | G23: BIG | H23: 3.4 | I23: 52.96 | J23: 40.42 | K23: 150.94 | L23: 150.94 | N23: 52.93 | O23: 40.29 | P23: 150.94 | Q23: 150.94 | R23: Aditi | S23: Full Rim
A24: 218062 | B24: 26L101A | C24: 218062.26L101A | D24: 65 | E24: 4 | F24: 0.062 | G24: SCRATCH | H24: 2.86 | R24: Aditi | S24: Rimless
A25: 234765 | B25: CIN-000001368366 | C25: 234765.CIN-000001368366 | D25: 12 | E25: 4 | F25: 0.333 | G25: BIG | H25: 9.5 | I25: 55.59 | J25: 39.9 | K25: 162.21 | L25: 162.21 | N25: 55.55 | O25: 39.85 | P25: 162.21 | Q25: 162.21 | R25: Aditi | S25: Full Rim
A26: 236095 | B26: IHR127B2C0000315 | C26: 236095.IHR127B2C0000315 | D26: 22 | E26: 4 | F26: 0.182 | G26: BIG | H26: 11 | I26: 50.5 | J26: 42.91 | K26: 152.32 | L26: 152.47 | N26: 50.35 | O26: 42.87 | P26: 152.32 | Q26: 152.47 | R26: Aditi | S26: Full Rim
